{
 "cells": [
  {
   "cell_type": "code",
   "execution_count": 3,
   "id": "8a399497",
   "metadata": {},
   "outputs": [
    {
     "name": "stdout",
     "output_type": "stream",
     "text": [
      "Collecting face-recognition\n",
      "  Using cached face_recognition-1.3.0-py2.py3-none-any.whl (15 kB)\n",
      "Requirement already satisfied: face-recognition-models>=0.3.0 in d:\\python\\lib\\site-packages (from face-recognition) (0.3.0)\n",
      "Collecting Click>=6.0\n",
      "  Using cached click-8.1.3-py3-none-any.whl (96 kB)\n",
      "Collecting dlib>=19.7\n",
      "  Using cached dlib-19.24.0.tar.gz (3.2 MB)\n",
      "  Preparing metadata (setup.py): started\n",
      "  Preparing metadata (setup.py): finished with status 'done'\n",
      "Requirement already satisfied: numpy in d:\\python\\lib\\site-packages (from face-recognition) (1.24.2)\n",
      "Requirement already satisfied: Pillow in d:\\python\\lib\\site-packages (from face-recognition) (9.4.0)\n",
      "Requirement already satisfied: colorama in d:\\python\\lib\\site-packages (from Click>=6.0->face-recognition) (0.4.6)\n",
      "Installing collected packages: dlib, Click, face-recognition\n",
      "  Running setup.py install for dlib: started\n",
      "  Running setup.py install for dlib: finished with status 'error'\n"
     ]
    },
    {
     "name": "stderr",
     "output_type": "stream",
     "text": [
      "  DEPRECATION: dlib is being installed using the legacy 'setup.py install' method, because it does not have a 'pyproject.toml' and the 'wheel' package is not installed. pip 23.1 will enforce this behaviour change. A possible replacement is to enable the '--use-pep517' option. Discussion can be found at https://github.com/pypa/pip/issues/8559\n",
      "  error: subprocess-exited-with-error\n",
      "  \n",
      "  Running setup.py install for dlib did not run successfully.\n",
      "  exit code: 1\n",
      "  \n",
      "  [75 lines of output]\n",
      "  running install\n",
      "  D:\\Python\\Lib\\site-packages\\setuptools\\command\\install.py:34: SetuptoolsDeprecationWarning: setup.py install is deprecated. Use build and pip and other standards-based tools.\n",
      "    warnings.warn(\n",
      "  running build\n",
      "  running build_py\n",
      "  running build_ext\n",
      "  C:\\Users\\nithi\\AppData\\Local\\Temp\\pip-install-3gc1kupg\\dlib_8be6fa986434465fb918e21b05d870bf\\setup.py:129: DeprecationWarning: distutils Version classes are deprecated. Use packaging.version instead.\n",
      "    if LooseVersion(cmake_version) < '3.1.0':\n",
      "  Building extension for Python 3.11.1 (tags/v3.11.1:a7a450f, Dec  6 2022, 19:58:39) [MSC v.1934 64 bit (AMD64)]\n",
      "  Invoking CMake setup: 'cmake C:\\Users\\nithi\\AppData\\Local\\Temp\\pip-install-3gc1kupg\\dlib_8be6fa986434465fb918e21b05d870bf\\tools\\python -DCMAKE_LIBRARY_OUTPUT_DIRECTORY=C:\\Users\\nithi\\AppData\\Local\\Temp\\pip-install-3gc1kupg\\dlib_8be6fa986434465fb918e21b05d870bf\\build\\lib.win-amd64-cpython-311 -DPYTHON_EXECUTABLE=D:\\Python\\python.exe -DCMAKE_LIBRARY_OUTPUT_DIRECTORY_RELEASE=C:\\Users\\nithi\\AppData\\Local\\Temp\\pip-install-3gc1kupg\\dlib_8be6fa986434465fb918e21b05d870bf\\build\\lib.win-amd64-cpython-311 -A x64'\n",
      "  -- Building for: NMake Makefiles\n",
      "  CMake Error at CMakeLists.txt:5 (message):\n",
      "  \n",
      "  \n",
      "  \n",
      "    !!!!!!!!!!!!!!!!!!!!!!!!!!!!!!!!!!!!!!!!!!!!!!!!!!!!!!!!!!!!!!!!!!!!!!!!!!!!!!!\n",
      "  \n",
      "  \n",
      "    You must use Visual Studio to build a python extension on windows.  If you\n",
      "    are getting this error it means you have not installed Visual C++.  Note\n",
      "    that there are many flavors of Visual Studio, like Visual Studio for C#\n",
      "    development.  You need to install Visual Studio for C++.\n",
      "  \n",
      "  \n",
      "    !!!!!!!!!!!!!!!!!!!!!!!!!!!!!!!!!!!!!!!!!!!!!!!!!!!!!!!!!!!!!!!!!!!!!!!!!!!!!!!\n",
      "  \n",
      "  \n",
      "  \n",
      "  \n",
      "  -- Configuring incomplete, errors occurred!\n",
      "  Traceback (most recent call last):\n",
      "    File \"<string>\", line 2, in <module>\n",
      "    File \"<pip-setuptools-caller>\", line 34, in <module>\n",
      "    File \"C:\\Users\\nithi\\AppData\\Local\\Temp\\pip-install-3gc1kupg\\dlib_8be6fa986434465fb918e21b05d870bf\\setup.py\", line 222, in <module>\n",
      "      setup(\n",
      "    File \"D:\\Python\\Lib\\site-packages\\setuptools\\__init__.py\", line 87, in setup\n",
      "      return distutils.core.setup(**attrs)\n",
      "             ^^^^^^^^^^^^^^^^^^^^^^^^^^^^^\n",
      "    File \"D:\\Python\\Lib\\site-packages\\setuptools\\_distutils\\core.py\", line 185, in setup\n",
      "      return run_commands(dist)\n",
      "             ^^^^^^^^^^^^^^^^^^\n",
      "    File \"D:\\Python\\Lib\\site-packages\\setuptools\\_distutils\\core.py\", line 201, in run_commands\n",
      "      dist.run_commands()\n",
      "    File \"D:\\Python\\Lib\\site-packages\\setuptools\\_distutils\\dist.py\", line 968, in run_commands\n",
      "      self.run_command(cmd)\n",
      "    File \"D:\\Python\\Lib\\site-packages\\setuptools\\dist.py\", line 1217, in run_command\n",
      "      super().run_command(command)\n",
      "    File \"D:\\Python\\Lib\\site-packages\\setuptools\\_distutils\\dist.py\", line 987, in run_command\n",
      "      cmd_obj.run()\n",
      "    File \"D:\\Python\\Lib\\site-packages\\setuptools\\command\\install.py\", line 68, in run\n",
      "      return orig.install.run(self)\n",
      "             ^^^^^^^^^^^^^^^^^^^^^^\n",
      "    File \"D:\\Python\\Lib\\site-packages\\setuptools\\_distutils\\command\\install.py\", line 698, in run\n",
      "      self.run_command('build')\n",
      "    File \"D:\\Python\\Lib\\site-packages\\setuptools\\_distutils\\cmd.py\", line 319, in run_command\n",
      "      self.distribution.run_command(command)\n",
      "    File \"D:\\Python\\Lib\\site-packages\\setuptools\\dist.py\", line 1217, in run_command\n",
      "      super().run_command(command)\n",
      "    File \"D:\\Python\\Lib\\site-packages\\setuptools\\_distutils\\dist.py\", line 987, in run_command\n",
      "      cmd_obj.run()\n",
      "    File \"D:\\Python\\Lib\\site-packages\\setuptools\\_distutils\\command\\build.py\", line 132, in run\n",
      "      self.run_command(cmd_name)\n",
      "    File \"D:\\Python\\Lib\\site-packages\\setuptools\\_distutils\\cmd.py\", line 319, in run_command\n",
      "      self.distribution.run_command(command)\n",
      "    File \"D:\\Python\\Lib\\site-packages\\setuptools\\dist.py\", line 1217, in run_command\n",
      "      super().run_command(command)\n",
      "    File \"D:\\Python\\Lib\\site-packages\\setuptools\\_distutils\\dist.py\", line 987, in run_command\n",
      "      cmd_obj.run()\n",
      "    File \"C:\\Users\\nithi\\AppData\\Local\\Temp\\pip-install-3gc1kupg\\dlib_8be6fa986434465fb918e21b05d870bf\\setup.py\", line 134, in run\n",
      "      self.build_extension(ext)\n",
      "    File \"C:\\Users\\nithi\\AppData\\Local\\Temp\\pip-install-3gc1kupg\\dlib_8be6fa986434465fb918e21b05d870bf\\setup.py\", line 171, in build_extension\n",
      "      subprocess.check_call(cmake_setup, cwd=build_folder)\n",
      "    File \"D:\\Python\\Lib\\subprocess.py\", line 413, in check_call\n",
      "      raise CalledProcessError(retcode, cmd)\n",
      "  subprocess.CalledProcessError: Command '['cmake', 'C:\\\\Users\\\\nithi\\\\AppData\\\\Local\\\\Temp\\\\pip-install-3gc1kupg\\\\dlib_8be6fa986434465fb918e21b05d870bf\\\\tools\\\\python', '-DCMAKE_LIBRARY_OUTPUT_DIRECTORY=C:\\\\Users\\\\nithi\\\\AppData\\\\Local\\\\Temp\\\\pip-install-3gc1kupg\\\\dlib_8be6fa986434465fb918e21b05d870bf\\\\build\\\\lib.win-amd64-cpython-311', '-DPYTHON_EXECUTABLE=D:\\\\Python\\\\python.exe', '-DCMAKE_LIBRARY_OUTPUT_DIRECTORY_RELEASE=C:\\\\Users\\\\nithi\\\\AppData\\\\Local\\\\Temp\\\\pip-install-3gc1kupg\\\\dlib_8be6fa986434465fb918e21b05d870bf\\\\build\\\\lib.win-amd64-cpython-311', '-A', 'x64']' returned non-zero exit status 1.\n",
      "  [end of output]\n",
      "  \n",
      "  note: This error originates from a subprocess, and is likely not a problem with pip.\n",
      "error: legacy-install-failure\n",
      "\n",
      "Encountered error while trying to install package.\n",
      "\n",
      "dlib\n",
      "\n",
      "note: This is an issue with the package mentioned above, not pip.\n",
      "hint: See above for output from the failure.\n"
     ]
    }
   ],
   "source": [
    "!pip install face-recognition"
   ]
  },
  {
   "cell_type": "code",
   "execution_count": null,
   "id": "d8e5d844",
   "metadata": {},
   "outputs": [],
   "source": []
  }
 ],
 "metadata": {
  "kernelspec": {
   "display_name": "Python 3 (ipykernel)",
   "language": "python",
   "name": "python3"
  },
  "language_info": {
   "codemirror_mode": {
    "name": "ipython",
    "version": 3
   },
   "file_extension": ".py",
   "mimetype": "text/x-python",
   "name": "python",
   "nbconvert_exporter": "python",
   "pygments_lexer": "ipython3",
   "version": "3.11.1"
  }
 },
 "nbformat": 4,
 "nbformat_minor": 5
}
